{
 "cells": [
  {
   "cell_type": "code",
   "execution_count": 1,
   "id": "bfbc14dd",
   "metadata": {},
   "outputs": [],
   "source": [
    "import tensorflow as tf\n",
    "import tensorflow_addons as tfa\n",
    "import tensorflow_datasets as tfds\n",
    "import matplotlib.pyplot as plt\n",
    "import sys\n",
    "sys.path.append(\"..\")\n",
    "sys.path.append(\"../src\")\n",
    "import os\n",
    "from src.DS_Generator import DataSet_Generator\n",
    "from src.model_evaluation import mean_average_precision\n",
    "from data_augmentation import *\n",
    "import numpy as np\n",
    "import pandas as pd\n",
    "import tensorflow_datasets as tfds\n",
    "from util import *\n",
    "import datetime\n",
    "%load_ext tensorboard"
   ]
  },
  {
   "cell_type": "markdown",
   "id": "06680c80",
   "metadata": {},
   "source": [
    "Okay Louis, such dir eine Batchsize aus. Bei mir hat nur 32 keine fehler verusacht."
   ]
  },
  {
   "cell_type": "code",
   "execution_count": 3,
   "id": "e377b10c",
   "metadata": {},
   "outputs": [],
   "source": [
    "# FÃ¼r deinen Model order\n",
    "if \"models\" not in os.listdir(\"../../\"):\n",
    "    os.makedirs(\"../../models\")\n",
    "    \n",
    "BATCH_SIZE = 32"
   ]
  },
  {
   "cell_type": "code",
   "execution_count": 4,
   "id": "9dbe983b",
   "metadata": {},
   "outputs": [
    {
     "name": "stdout",
     "output_type": "stream",
     "text": [
      "We threw away the datapoint with index 50035 \n"
     ]
    }
   ],
   "source": [
    "train_ds, val_ds = DataSet_Generator().generate_species_data(TRAIN_SPECIES_DF,augment=1,batch_size=BATCH_SIZE)\n",
    "num_classes = len(set(TRAIN_SPECIES_DF[\"species\"]))"
   ]
  },
  {
   "cell_type": "code",
   "execution_count": 7,
   "id": "a0cf3da3",
   "metadata": {},
   "outputs": [],
   "source": [
    "Input = tf.keras.Input((224,224,3))\n",
    "base = tf.keras.applications.inception_v3.InceptionV3(weights=\"imagenet\", include_top=False,input_tensor=Input)\n",
    "flatten = base.output\n",
    "flatten = tf.keras.layers.Flatten()(flatten)\n",
    "head = tf.keras.layers.Dense(256, activation=\"relu\",kernel_regularizer=tf.keras.regularizers.l2(0.001))(flatten)\n",
    "head = tf.keras.layers.Dense(128, activation=\"relu\",kernel_regularizer=tf.keras.regularizers.l2(0.001))(head)\n",
    "head = tf.keras.layers.Dense(64, activation=\"relu\",kernel_regularizer=tf.keras.regularizers.l2(0.001))(head)\n",
    "head = tf.keras.layers.Dense(num_classes,activation=\"softmax\")(head)\n",
    "model = tf.keras.Model(inputs=Input, outputs=head,name=\"Inception_v3_with_imagenet_weights_and_l2\")\n",
    "\n",
    "model.compile(optimizer=tf.keras.optimizers.Adam(0.001),loss=\"categorical_crossentropy\",metrics=[\"acc\"])\n",
    "\n",
    "if model.name not in os.listdir(\"../../models/\"):\n",
    "    os.makedirs(\"../../models/\"+model.name)\n",
    "    os.makedirs(\"../../models/\"+model.name+\"/logs\")\n",
    "    os.makedirs(\"../../models/\"+model.name+\"/saves\")\n",
    "    \n",
    "time_stamp = datetime.datetime.now().strftime(\"%Y%m%d-%H%M%S\")\n",
    "\n",
    "log_dir = \"../../models/\"+model.name+\"/logs/\" +time_stamp \n",
    "\n",
    "tensorboard_callback = tf.keras.callbacks.TensorBoard(log_dir=log_dir, histogram_freq=1)\n",
    "\n",
    "checkpoint_path = \"../../models/\"+model.name+\"/saves/\" +time_stamp +\"/cp-{epoch:04d}.ckpt\"\n",
    "\n",
    "cp_callback = tf.keras.callbacks.ModelCheckpoint(\n",
    "    filepath=checkpoint_path, \n",
    "    verbose=1, \n",
    "    save_weights_only=True)"
   ]
  },
  {
   "cell_type": "code",
   "execution_count": 8,
   "id": "ab97ac0f",
   "metadata": {},
   "outputs": [
    {
     "name": "stdout",
     "output_type": "stream",
     "text": [
      "Epoch 1/15\n"
     ]
    },
    {
     "ename": "UnimplementedError",
     "evalue": "Graph execution error:\n\nDetected at node 'Inception_v3_with_imagenet_weights_and_l2/conv2d_94/Conv2D' defined at (most recent call last):\n    File \"C:\\Users\\Felix\\anaconda3\\lib\\runpy.py\", line 197, in _run_module_as_main\n      return _run_code(code, main_globals, None,\n    File \"C:\\Users\\Felix\\anaconda3\\lib\\runpy.py\", line 87, in _run_code\n      exec(code, run_globals)\n    File \"C:\\Users\\Felix\\AppData\\Roaming\\Python\\Python39\\site-packages\\ipykernel_launcher.py\", line 16, in <module>\n      app.launch_new_instance()\n    File \"C:\\Users\\Felix\\AppData\\Roaming\\Python\\Python39\\site-packages\\traitlets\\config\\application.py\", line 846, in launch_instance\n      app.start()\n    File \"C:\\Users\\Felix\\AppData\\Roaming\\Python\\Python39\\site-packages\\ipykernel\\kernelapp.py\", line 677, in start\n      self.io_loop.start()\n    File \"C:\\Users\\Felix\\AppData\\Roaming\\Python\\Python39\\site-packages\\tornado\\platform\\asyncio.py\", line 199, in start\n      self.asyncio_loop.run_forever()\n    File \"C:\\Users\\Felix\\anaconda3\\lib\\asyncio\\base_events.py\", line 596, in run_forever\n      self._run_once()\n    File \"C:\\Users\\Felix\\anaconda3\\lib\\asyncio\\base_events.py\", line 1890, in _run_once\n      handle._run()\n    File \"C:\\Users\\Felix\\anaconda3\\lib\\asyncio\\events.py\", line 80, in _run\n      self._context.run(self._callback, *self._args)\n    File \"C:\\Users\\Felix\\AppData\\Roaming\\Python\\Python39\\site-packages\\ipykernel\\kernelbase.py\", line 473, in dispatch_queue\n      await self.process_one()\n    File \"C:\\Users\\Felix\\AppData\\Roaming\\Python\\Python39\\site-packages\\ipykernel\\kernelbase.py\", line 462, in process_one\n      await dispatch(*args)\n    File \"C:\\Users\\Felix\\AppData\\Roaming\\Python\\Python39\\site-packages\\ipykernel\\kernelbase.py\", line 369, in dispatch_shell\n      await result\n    File \"C:\\Users\\Felix\\AppData\\Roaming\\Python\\Python39\\site-packages\\ipykernel\\kernelbase.py\", line 664, in execute_request\n      reply_content = await reply_content\n    File \"C:\\Users\\Felix\\AppData\\Roaming\\Python\\Python39\\site-packages\\ipykernel\\ipkernel.py\", line 355, in do_execute\n      res = shell.run_cell(code, store_history=store_history, silent=silent)\n    File \"C:\\Users\\Felix\\AppData\\Roaming\\Python\\Python39\\site-packages\\ipykernel\\zmqshell.py\", line 532, in run_cell\n      return super().run_cell(*args, **kwargs)\n    File \"C:\\Users\\Felix\\AppData\\Roaming\\Python\\Python39\\site-packages\\IPython\\core\\interactiveshell.py\", line 2854, in run_cell\n      result = self._run_cell(\n    File \"C:\\Users\\Felix\\AppData\\Roaming\\Python\\Python39\\site-packages\\IPython\\core\\interactiveshell.py\", line 2900, in _run_cell\n      return runner(coro)\n    File \"C:\\Users\\Felix\\AppData\\Roaming\\Python\\Python39\\site-packages\\IPython\\core\\async_helpers.py\", line 129, in _pseudo_sync_runner\n      coro.send(None)\n    File \"C:\\Users\\Felix\\AppData\\Roaming\\Python\\Python39\\site-packages\\IPython\\core\\interactiveshell.py\", line 3098, in run_cell_async\n      has_raised = await self.run_ast_nodes(code_ast.body, cell_name,\n    File \"C:\\Users\\Felix\\AppData\\Roaming\\Python\\Python39\\site-packages\\IPython\\core\\interactiveshell.py\", line 3301, in run_ast_nodes\n      if await self.run_code(code, result, async_=asy):\n    File \"C:\\Users\\Felix\\AppData\\Roaming\\Python\\Python39\\site-packages\\IPython\\core\\interactiveshell.py\", line 3361, in run_code\n      exec(code_obj, self.user_global_ns, self.user_ns)\n    File \"C:\\Users\\Felix\\AppData\\Local\\Temp\\ipykernel_6136\\63926395.py\", line 1, in <cell line: 1>\n      model.fit(\n    File \"C:\\Users\\Felix\\anaconda3\\lib\\site-packages\\keras\\utils\\traceback_utils.py\", line 64, in error_handler\n      return fn(*args, **kwargs)\n    File \"C:\\Users\\Felix\\anaconda3\\lib\\site-packages\\keras\\engine\\training.py\", line 1384, in fit\n      tmp_logs = self.train_function(iterator)\n    File \"C:\\Users\\Felix\\anaconda3\\lib\\site-packages\\keras\\engine\\training.py\", line 1021, in train_function\n      return step_function(self, iterator)\n    File \"C:\\Users\\Felix\\anaconda3\\lib\\site-packages\\keras\\engine\\training.py\", line 1010, in step_function\n      outputs = model.distribute_strategy.run(run_step, args=(data,))\n    File \"C:\\Users\\Felix\\anaconda3\\lib\\site-packages\\keras\\engine\\training.py\", line 1000, in run_step\n      outputs = model.train_step(data)\n    File \"C:\\Users\\Felix\\anaconda3\\lib\\site-packages\\keras\\engine\\training.py\", line 859, in train_step\n      y_pred = self(x, training=True)\n    File \"C:\\Users\\Felix\\anaconda3\\lib\\site-packages\\keras\\utils\\traceback_utils.py\", line 64, in error_handler\n      return fn(*args, **kwargs)\n    File \"C:\\Users\\Felix\\anaconda3\\lib\\site-packages\\keras\\engine\\base_layer.py\", line 1096, in __call__\n      outputs = call_fn(inputs, *args, **kwargs)\n    File \"C:\\Users\\Felix\\anaconda3\\lib\\site-packages\\keras\\utils\\traceback_utils.py\", line 92, in error_handler\n      return fn(*args, **kwargs)\n    File \"C:\\Users\\Felix\\anaconda3\\lib\\site-packages\\keras\\engine\\functional.py\", line 451, in call\n      return self._run_internal_graph(\n    File \"C:\\Users\\Felix\\anaconda3\\lib\\site-packages\\keras\\engine\\functional.py\", line 589, in _run_internal_graph\n      outputs = node.layer(*args, **kwargs)\n    File \"C:\\Users\\Felix\\anaconda3\\lib\\site-packages\\keras\\utils\\traceback_utils.py\", line 64, in error_handler\n      return fn(*args, **kwargs)\n    File \"C:\\Users\\Felix\\anaconda3\\lib\\site-packages\\keras\\engine\\base_layer.py\", line 1096, in __call__\n      outputs = call_fn(inputs, *args, **kwargs)\n    File \"C:\\Users\\Felix\\anaconda3\\lib\\site-packages\\keras\\utils\\traceback_utils.py\", line 92, in error_handler\n      return fn(*args, **kwargs)\n    File \"C:\\Users\\Felix\\anaconda3\\lib\\site-packages\\keras\\layers\\convolutional.py\", line 248, in call\n      outputs = self.convolution_op(inputs, self.kernel)\n    File \"C:\\Users\\Felix\\anaconda3\\lib\\site-packages\\keras\\layers\\convolutional.py\", line 233, in convolution_op\n      return tf.nn.convolution(\nNode: 'Inception_v3_with_imagenet_weights_and_l2/conv2d_94/Conv2D'\nDNN library is not found.\n\t [[{{node Inception_v3_with_imagenet_weights_and_l2/conv2d_94/Conv2D}}]] [Op:__inference_train_function_22158]",
     "output_type": "error",
     "traceback": [
      "\u001b[1;31m---------------------------------------------------------------------------\u001b[0m",
      "\u001b[1;31mUnimplementedError\u001b[0m                        Traceback (most recent call last)",
      "Input \u001b[1;32mIn [8]\u001b[0m, in \u001b[0;36m<cell line: 1>\u001b[1;34m()\u001b[0m\n\u001b[1;32m----> 1\u001b[0m \u001b[43mmodel\u001b[49m\u001b[38;5;241;43m.\u001b[39;49m\u001b[43mfit\u001b[49m\u001b[43m(\u001b[49m\n\u001b[0;32m      2\u001b[0m \u001b[43mtrain_ds\u001b[49m\u001b[43m,\u001b[49m\n\u001b[0;32m      3\u001b[0m \u001b[43mepochs\u001b[49m\u001b[38;5;241;43m=\u001b[39;49m\u001b[38;5;241;43m15\u001b[39;49m\u001b[43m,\u001b[49m\n\u001b[0;32m      4\u001b[0m \u001b[43mvalidation_data\u001b[49m\u001b[38;5;241;43m=\u001b[39;49m\u001b[43mval_ds\u001b[49m\u001b[43m,\u001b[49m\n\u001b[0;32m      5\u001b[0m \u001b[43mcallbacks\u001b[49m\u001b[38;5;241;43m=\u001b[39;49m\u001b[43m[\u001b[49m\u001b[43mcp_callback\u001b[49m\u001b[43m,\u001b[49m\u001b[43mtensorboard_callback\u001b[49m\u001b[43m]\u001b[49m\u001b[43m)\u001b[49m\n",
      "File \u001b[1;32m~\\anaconda3\\lib\\site-packages\\keras\\utils\\traceback_utils.py:67\u001b[0m, in \u001b[0;36mfilter_traceback.<locals>.error_handler\u001b[1;34m(*args, **kwargs)\u001b[0m\n\u001b[0;32m     65\u001b[0m \u001b[38;5;28;01mexcept\u001b[39;00m \u001b[38;5;167;01mException\u001b[39;00m \u001b[38;5;28;01mas\u001b[39;00m e:  \u001b[38;5;66;03m# pylint: disable=broad-except\u001b[39;00m\n\u001b[0;32m     66\u001b[0m   filtered_tb \u001b[38;5;241m=\u001b[39m _process_traceback_frames(e\u001b[38;5;241m.\u001b[39m__traceback__)\n\u001b[1;32m---> 67\u001b[0m   \u001b[38;5;28;01mraise\u001b[39;00m e\u001b[38;5;241m.\u001b[39mwith_traceback(filtered_tb) \u001b[38;5;28;01mfrom\u001b[39;00m \u001b[38;5;28mNone\u001b[39m\n\u001b[0;32m     68\u001b[0m \u001b[38;5;28;01mfinally\u001b[39;00m:\n\u001b[0;32m     69\u001b[0m   \u001b[38;5;28;01mdel\u001b[39;00m filtered_tb\n",
      "File \u001b[1;32m~\\anaconda3\\lib\\site-packages\\tensorflow\\python\\eager\\execute.py:54\u001b[0m, in \u001b[0;36mquick_execute\u001b[1;34m(op_name, num_outputs, inputs, attrs, ctx, name)\u001b[0m\n\u001b[0;32m     52\u001b[0m \u001b[38;5;28;01mtry\u001b[39;00m:\n\u001b[0;32m     53\u001b[0m   ctx\u001b[38;5;241m.\u001b[39mensure_initialized()\n\u001b[1;32m---> 54\u001b[0m   tensors \u001b[38;5;241m=\u001b[39m pywrap_tfe\u001b[38;5;241m.\u001b[39mTFE_Py_Execute(ctx\u001b[38;5;241m.\u001b[39m_handle, device_name, op_name,\n\u001b[0;32m     55\u001b[0m                                       inputs, attrs, num_outputs)\n\u001b[0;32m     56\u001b[0m \u001b[38;5;28;01mexcept\u001b[39;00m core\u001b[38;5;241m.\u001b[39m_NotOkStatusException \u001b[38;5;28;01mas\u001b[39;00m e:\n\u001b[0;32m     57\u001b[0m   \u001b[38;5;28;01mif\u001b[39;00m name \u001b[38;5;129;01mis\u001b[39;00m \u001b[38;5;129;01mnot\u001b[39;00m \u001b[38;5;28;01mNone\u001b[39;00m:\n",
      "\u001b[1;31mUnimplementedError\u001b[0m: Graph execution error:\n\nDetected at node 'Inception_v3_with_imagenet_weights_and_l2/conv2d_94/Conv2D' defined at (most recent call last):\n    File \"C:\\Users\\Felix\\anaconda3\\lib\\runpy.py\", line 197, in _run_module_as_main\n      return _run_code(code, main_globals, None,\n    File \"C:\\Users\\Felix\\anaconda3\\lib\\runpy.py\", line 87, in _run_code\n      exec(code, run_globals)\n    File \"C:\\Users\\Felix\\AppData\\Roaming\\Python\\Python39\\site-packages\\ipykernel_launcher.py\", line 16, in <module>\n      app.launch_new_instance()\n    File \"C:\\Users\\Felix\\AppData\\Roaming\\Python\\Python39\\site-packages\\traitlets\\config\\application.py\", line 846, in launch_instance\n      app.start()\n    File \"C:\\Users\\Felix\\AppData\\Roaming\\Python\\Python39\\site-packages\\ipykernel\\kernelapp.py\", line 677, in start\n      self.io_loop.start()\n    File \"C:\\Users\\Felix\\AppData\\Roaming\\Python\\Python39\\site-packages\\tornado\\platform\\asyncio.py\", line 199, in start\n      self.asyncio_loop.run_forever()\n    File \"C:\\Users\\Felix\\anaconda3\\lib\\asyncio\\base_events.py\", line 596, in run_forever\n      self._run_once()\n    File \"C:\\Users\\Felix\\anaconda3\\lib\\asyncio\\base_events.py\", line 1890, in _run_once\n      handle._run()\n    File \"C:\\Users\\Felix\\anaconda3\\lib\\asyncio\\events.py\", line 80, in _run\n      self._context.run(self._callback, *self._args)\n    File \"C:\\Users\\Felix\\AppData\\Roaming\\Python\\Python39\\site-packages\\ipykernel\\kernelbase.py\", line 473, in dispatch_queue\n      await self.process_one()\n    File \"C:\\Users\\Felix\\AppData\\Roaming\\Python\\Python39\\site-packages\\ipykernel\\kernelbase.py\", line 462, in process_one\n      await dispatch(*args)\n    File \"C:\\Users\\Felix\\AppData\\Roaming\\Python\\Python39\\site-packages\\ipykernel\\kernelbase.py\", line 369, in dispatch_shell\n      await result\n    File \"C:\\Users\\Felix\\AppData\\Roaming\\Python\\Python39\\site-packages\\ipykernel\\kernelbase.py\", line 664, in execute_request\n      reply_content = await reply_content\n    File \"C:\\Users\\Felix\\AppData\\Roaming\\Python\\Python39\\site-packages\\ipykernel\\ipkernel.py\", line 355, in do_execute\n      res = shell.run_cell(code, store_history=store_history, silent=silent)\n    File \"C:\\Users\\Felix\\AppData\\Roaming\\Python\\Python39\\site-packages\\ipykernel\\zmqshell.py\", line 532, in run_cell\n      return super().run_cell(*args, **kwargs)\n    File \"C:\\Users\\Felix\\AppData\\Roaming\\Python\\Python39\\site-packages\\IPython\\core\\interactiveshell.py\", line 2854, in run_cell\n      result = self._run_cell(\n    File \"C:\\Users\\Felix\\AppData\\Roaming\\Python\\Python39\\site-packages\\IPython\\core\\interactiveshell.py\", line 2900, in _run_cell\n      return runner(coro)\n    File \"C:\\Users\\Felix\\AppData\\Roaming\\Python\\Python39\\site-packages\\IPython\\core\\async_helpers.py\", line 129, in _pseudo_sync_runner\n      coro.send(None)\n    File \"C:\\Users\\Felix\\AppData\\Roaming\\Python\\Python39\\site-packages\\IPython\\core\\interactiveshell.py\", line 3098, in run_cell_async\n      has_raised = await self.run_ast_nodes(code_ast.body, cell_name,\n    File \"C:\\Users\\Felix\\AppData\\Roaming\\Python\\Python39\\site-packages\\IPython\\core\\interactiveshell.py\", line 3301, in run_ast_nodes\n      if await self.run_code(code, result, async_=asy):\n    File \"C:\\Users\\Felix\\AppData\\Roaming\\Python\\Python39\\site-packages\\IPython\\core\\interactiveshell.py\", line 3361, in run_code\n      exec(code_obj, self.user_global_ns, self.user_ns)\n    File \"C:\\Users\\Felix\\AppData\\Local\\Temp\\ipykernel_6136\\63926395.py\", line 1, in <cell line: 1>\n      model.fit(\n    File \"C:\\Users\\Felix\\anaconda3\\lib\\site-packages\\keras\\utils\\traceback_utils.py\", line 64, in error_handler\n      return fn(*args, **kwargs)\n    File \"C:\\Users\\Felix\\anaconda3\\lib\\site-packages\\keras\\engine\\training.py\", line 1384, in fit\n      tmp_logs = self.train_function(iterator)\n    File \"C:\\Users\\Felix\\anaconda3\\lib\\site-packages\\keras\\engine\\training.py\", line 1021, in train_function\n      return step_function(self, iterator)\n    File \"C:\\Users\\Felix\\anaconda3\\lib\\site-packages\\keras\\engine\\training.py\", line 1010, in step_function\n      outputs = model.distribute_strategy.run(run_step, args=(data,))\n    File \"C:\\Users\\Felix\\anaconda3\\lib\\site-packages\\keras\\engine\\training.py\", line 1000, in run_step\n      outputs = model.train_step(data)\n    File \"C:\\Users\\Felix\\anaconda3\\lib\\site-packages\\keras\\engine\\training.py\", line 859, in train_step\n      y_pred = self(x, training=True)\n    File \"C:\\Users\\Felix\\anaconda3\\lib\\site-packages\\keras\\utils\\traceback_utils.py\", line 64, in error_handler\n      return fn(*args, **kwargs)\n    File \"C:\\Users\\Felix\\anaconda3\\lib\\site-packages\\keras\\engine\\base_layer.py\", line 1096, in __call__\n      outputs = call_fn(inputs, *args, **kwargs)\n    File \"C:\\Users\\Felix\\anaconda3\\lib\\site-packages\\keras\\utils\\traceback_utils.py\", line 92, in error_handler\n      return fn(*args, **kwargs)\n    File \"C:\\Users\\Felix\\anaconda3\\lib\\site-packages\\keras\\engine\\functional.py\", line 451, in call\n      return self._run_internal_graph(\n    File \"C:\\Users\\Felix\\anaconda3\\lib\\site-packages\\keras\\engine\\functional.py\", line 589, in _run_internal_graph\n      outputs = node.layer(*args, **kwargs)\n    File \"C:\\Users\\Felix\\anaconda3\\lib\\site-packages\\keras\\utils\\traceback_utils.py\", line 64, in error_handler\n      return fn(*args, **kwargs)\n    File \"C:\\Users\\Felix\\anaconda3\\lib\\site-packages\\keras\\engine\\base_layer.py\", line 1096, in __call__\n      outputs = call_fn(inputs, *args, **kwargs)\n    File \"C:\\Users\\Felix\\anaconda3\\lib\\site-packages\\keras\\utils\\traceback_utils.py\", line 92, in error_handler\n      return fn(*args, **kwargs)\n    File \"C:\\Users\\Felix\\anaconda3\\lib\\site-packages\\keras\\layers\\convolutional.py\", line 248, in call\n      outputs = self.convolution_op(inputs, self.kernel)\n    File \"C:\\Users\\Felix\\anaconda3\\lib\\site-packages\\keras\\layers\\convolutional.py\", line 233, in convolution_op\n      return tf.nn.convolution(\nNode: 'Inception_v3_with_imagenet_weights_and_l2/conv2d_94/Conv2D'\nDNN library is not found.\n\t [[{{node Inception_v3_with_imagenet_weights_and_l2/conv2d_94/Conv2D}}]] [Op:__inference_train_function_22158]"
     ]
    }
   ],
   "source": [
    "model.fit(\n",
    "train_ds,\n",
    "epochs=15,\n",
    "validation_data=val_ds,\n",
    "callbacks=[cp_callback,tensorboard_callback])"
   ]
  },
  {
   "cell_type": "code",
   "execution_count": null,
   "id": "ff2fb636",
   "metadata": {},
   "outputs": [],
   "source": []
  }
 ],
 "metadata": {
  "kernelspec": {
   "display_name": "whale",
   "language": "python",
   "name": "whale"
  },
  "language_info": {
   "codemirror_mode": {
    "name": "ipython",
    "version": 3
   },
   "file_extension": ".py",
   "mimetype": "text/x-python",
   "name": "python",
   "nbconvert_exporter": "python",
   "pygments_lexer": "ipython3",
   "version": "3.9.7"
  }
 },
 "nbformat": 4,
 "nbformat_minor": 5
}
